WARNING:accelerate.utils.modeling:The model weights are not tied. Please use the `tie_weights` method before using the `infer_auto_device` function.
Loading checkpoint shards:   0%|          | 0/5 [00:00<?, ?it/s]Loading checkpoint shards:  20%|██        | 1/5 [00:03<00:15,  3.91s/it]Loading checkpoint shards:  40%|████      | 2/5 [00:07<00:11,  3.72s/it]Loading checkpoint shards:  60%|██████    | 3/5 [00:10<00:07,  3.57s/it]Loading checkpoint shards:  80%|████████  | 4/5 [00:14<00:03,  3.53s/it]Loading checkpoint shards: 100%|██████████| 5/5 [00:15<00:00,  2.69s/it]Loading checkpoint shards: 100%|██████████| 5/5 [00:15<00:00,  3.12s/it]
Unused kwargs: ['bnb_8bit_quant_type', 'bnb_8bit_compute_dtype', 'bnb_8bit_use_double_quant']. These kwargs are not used in <class 'transformers.utils.quantization_config.BitsAndBytesConfig'>.
Traceback (most recent call last):
  File "/scratch/oe2015/conda-envs/greedy/lib/python3.9/site-packages/transformers/utils/hub.py", line 403, in cached_file
    resolved_file = hf_hub_download(
  File "/scratch/oe2015/conda-envs/greedy/lib/python3.9/site-packages/huggingface_hub/utils/_validators.py", line 106, in _inner_fn
    validate_repo_id(arg_value)
  File "/scratch/oe2015/conda-envs/greedy/lib/python3.9/site-packages/huggingface_hub/utils/_validators.py", line 154, in validate_repo_id
    raise HFValidationError(
huggingface_hub.errors.HFValidationError: Repo id must be in the form 'repo_name' or 'namespace/repo_name': 'DeTikZify/detikzify/evaluate/final_model_checkpoint_512_quant'. Use `repo_type` argument if needed.

The above exception was the direct cause of the following exception:

Traceback (most recent call last):
  File "/scratch/oe2015/ai_project/DeTikZify/detikzify/evaluate/omar.py", line 65, in <module>
    model = MllamaForCausalLM.from_pretrained(
  File "/scratch/oe2015/conda-envs/greedy/lib/python3.9/site-packages/transformers/modeling_utils.py", line 3506, in from_pretrained
    resolved_config_file = cached_file(
  File "/scratch/oe2015/conda-envs/greedy/lib/python3.9/site-packages/transformers/utils/hub.py", line 469, in cached_file
    raise EnvironmentError(
OSError: Incorrect path_or_model_id: 'DeTikZify/detikzify/evaluate/final_model_checkpoint_512_quant'. Please provide either the path to a local folder or the repo_id of a model on the Hub.
