WARNING:accelerate.utils.modeling:The model weights are not tied. Please use the `tie_weights` method before using the `infer_auto_device` function.
cuda
Loading checkpoint shards:   0%|          | 0/5 [00:00<?, ?it/s]Loading checkpoint shards:  20%|██        | 1/5 [00:08<00:34,  8.66s/it]Loading checkpoint shards:  40%|████      | 2/5 [00:13<00:19,  6.65s/it]Loading checkpoint shards:  60%|██████    | 3/5 [00:18<00:11,  5.67s/it]Loading checkpoint shards:  80%|████████  | 4/5 [00:23<00:05,  5.32s/it]Loading checkpoint shards: 100%|██████████| 5/5 [00:24<00:00,  3.93s/it]Loading checkpoint shards: 100%|██████████| 5/5 [00:24<00:00,  4.93s/it]
Traceback (most recent call last):
  File "/scratch/oe2015/conda-envs/greedy/lib/python3.9/site-packages/huggingface_hub/utils/_http.py", line 406, in hf_raise_for_status
    response.raise_for_status()
  File "/scratch/oe2015/conda-envs/greedy/lib/python3.9/site-packages/requests/models.py", line 1024, in raise_for_status
    raise HTTPError(http_error_msg, response=self)
requests.exceptions.HTTPError: 404 Client Error: Not Found for url: https://huggingface.co/final_model_checkpoint/resolve/main/adapter_config.json

The above exception was the direct cause of the following exception:

Traceback (most recent call last):
  File "/scratch/oe2015/conda-envs/greedy/lib/python3.9/site-packages/peft/config.py", line 205, in _get_peft_type
    config_file = hf_hub_download(
  File "/scratch/oe2015/conda-envs/greedy/lib/python3.9/site-packages/huggingface_hub/utils/_validators.py", line 114, in _inner_fn
    return fn(*args, **kwargs)
  File "/scratch/oe2015/conda-envs/greedy/lib/python3.9/site-packages/huggingface_hub/file_download.py", line 862, in hf_hub_download
    return _hf_hub_download_to_cache_dir(
  File "/scratch/oe2015/conda-envs/greedy/lib/python3.9/site-packages/huggingface_hub/file_download.py", line 969, in _hf_hub_download_to_cache_dir
    _raise_on_head_call_error(head_call_error, force_download, local_files_only)
  File "/scratch/oe2015/conda-envs/greedy/lib/python3.9/site-packages/huggingface_hub/file_download.py", line 1484, in _raise_on_head_call_error
    raise head_call_error
  File "/scratch/oe2015/conda-envs/greedy/lib/python3.9/site-packages/huggingface_hub/file_download.py", line 1376, in _get_metadata_or_catch_error
    metadata = get_hf_file_metadata(
  File "/scratch/oe2015/conda-envs/greedy/lib/python3.9/site-packages/huggingface_hub/utils/_validators.py", line 114, in _inner_fn
    return fn(*args, **kwargs)
  File "/scratch/oe2015/conda-envs/greedy/lib/python3.9/site-packages/huggingface_hub/file_download.py", line 1296, in get_hf_file_metadata
    r = _request_wrapper(
  File "/scratch/oe2015/conda-envs/greedy/lib/python3.9/site-packages/huggingface_hub/file_download.py", line 277, in _request_wrapper
    response = _request_wrapper(
  File "/scratch/oe2015/conda-envs/greedy/lib/python3.9/site-packages/huggingface_hub/file_download.py", line 301, in _request_wrapper
    hf_raise_for_status(response)
  File "/scratch/oe2015/conda-envs/greedy/lib/python3.9/site-packages/huggingface_hub/utils/_http.py", line 454, in hf_raise_for_status
    raise _format(RepositoryNotFoundError, message, response) from e
huggingface_hub.errors.RepositoryNotFoundError: 404 Client Error. (Request ID: Root=1-6735c9cc-3a136c9b542c90171c3b34c2;3c8f0145-5408-471c-83fb-08c0b2296b30)

Repository Not Found for url: https://huggingface.co/final_model_checkpoint/resolve/main/adapter_config.json.
Please make sure you specified the correct `repo_id` and `repo_type`.
If you are trying to access a private or gated repo, make sure you are authenticated.

During handling of the above exception, another exception occurred:

Traceback (most recent call last):
  File "/scratch/oe2015/ai_project/DeTikZify/detikzify/evaluate/run.py", line 31, in <module>
    model = PeftModel.from_pretrained(model, final_model_path)
  File "/scratch/oe2015/conda-envs/greedy/lib/python3.9/site-packages/peft/peft_model.py", line 484, in from_pretrained
    PeftConfig._get_peft_type(
  File "/scratch/oe2015/conda-envs/greedy/lib/python3.9/site-packages/peft/config.py", line 211, in _get_peft_type
    raise ValueError(f"Can't find '{CONFIG_NAME}' at '{model_id}'")
ValueError: Can't find 'adapter_config.json' at 'final_model_checkpoint'
